Workbook

Sheet Cover
B3: Baseball Hitting Development Workbook
B5: 40 hitting drills · medicine-ball support · warm-ups · troubleshooting · mental approach · parents' guide · progress dashboard · parent reports
B7: Integrated edition v1.0
B10: Workbook details
B11: Team / organization
B12: Coach
B13: Season
B14: Workbook owner
B15: Last updated
B17: Inside
B18: 40 | C18: hitting drills (H01–H40) | D18: 14 | E18: medicine-ball exercises | F18: 18 | G18: troubleshooting guides
B20: 6 | C20: warm-up routines | D20: 8 | E20: session templates | F20: 1 | G20: dashboard + parent report
B23: Start here → Contents
B25: Suggested sets, reps, and rounds are coaching starting points, not individualized prescriptions. Adjust to age, experience, health, and total baseball workload. Stop for pain.

Sheet Contents
B1: ← Contents
B2: Table of Contents
B3: Click any sheet name to jump to it. Every sheet has a '← Contents' link in cell B1.
B5: # | C5: Section | D5: Sheet | E5: What it contains
B6: 1 | C6: Start | D6: Cover | E6: Title page
B7: 2 | C7: Start | D7: Contents | E7: Clickable table of contents
B8: 3 | C8: Start | D8: How To Use | E8: Quick-start steps and conventions
B9: 4 | C9: Players & goals | D9: Players | E9: Roster: Player ID, readiness, current focus, cue, review date
B10: 5 | C10: Hitting library | D10: Drill Index | E10: All 40 hitting drills with links
B11: 6 | C11: Hitting library | D11: Hitting Drills | E11: Full library H01–H40: setup, steps, cues, mistakes, progressions
B12: 7 | C12: Supporting training | D12: Med Ball Library | E12: 14 medicine-ball exercises (M01–M14) with hitting pairings
B13: 8 | C13: Supporting training | D13: Med Ball Progression | E13: 5-stage progression, readiness, ball weight, doses, mistakes
B14: 9 | C14: Supporting training | D14: Youth Games | E14: 5 youth games (G01–G05)
B15: 10 | C15: Supporting training | D15: Rehearsals | E15: Dry rehearsals and feedback tools (R01–R07)
B16: 11 | C16: Preparation | D16: Warm-Up Routines | E16: 6 warm-up routines (WR1–WR6)
B17: 12 | C17: Preparation | D17: Warm-Up Library | E17: 14 warm-up activities (WU01–WU14)
... B32: 27 | C32: Reference | D32: Basis & Limits | E32: Basis and limitations

Sheet How To Use
B1: ← Contents
B2: How To Use This Workbook
B5: Step | C5: Task | D5: How
B6: 1 | C6: Add players | D6: Enter each player once on Players with a unique Player ID (e.g., P001). All logs and the dashboard use the ID, not the name.
B7: 2 | C7: Set a goal | D7: For each player record one current focus, one cue, assigned drill IDs, and a review date on Players.
B8: 3 | C8: Plan practice | D8: Pick a template on Session Builder, or build your own from Drill Index, Troubleshooting, and Warm-Up Routines.
B9: 4 | C9: Log practice | D9: Enter one row per drill round on Practice Log. Choose Player ID, Context, and Drill ID from the dropdowns. Leave a measure blank if you did not assess it — blank is not zero.
B10: 5 | C10: Practice minutes | D10: Enter minutes on each round row for the time that round took (do not repeat the whole session's minutes on every row).
B11: 6 | C11: Check entries | D11: The 'Entry check' column flags impossible counts (e.g., solid contacts > swings). Fix flagged rows before reporting.
B12: 7 | C12: Review progress | D12: On Dashboard choose a Player ID, start/end dates, and context. Optionally enter a baseline period to compare.
B13: 8 | C13: Write the parent report | D13: On Parent Report type the three comment boxes (what went well, next focus, optional home task).
B14: 9 | C14: Export | D14: Desktop Excel: run the ExportPlayerReport macro (see Export & Macro Guide) or File → Save As → PDF with only the Parent Report sheet selected.
B15: 10 | C15: Back up | D15: Save a dated copy regularly. Do not send the whole workbook to parents — it contains every player's data.
B17: Conventions
C18: Item | D18: Meaning
C19: Yellow cells | D19: Inputs you type or choose
C20: Navy headers | D20: Table headers
C21: H01–H40 | D21: Hitting drills (the 40-drill count)
C22: M01–M14 | D22: Medicine-ball exercises (supporting, not counted as hitting drills)
C23: G01–G05 | D23: Youth games
C24: R01–R07 | D24: Rehearsal and feedback tools
C25: WR / WU | D25: Warm-up routines / warm-up activities
C26: T01–T18 | D26: Troubleshooting guides
C27: S1–S8 | D27: Session templates

Sheet Players
B1: ← Contents
B2: Players & Goals
B3: One row per player. Player ID must be unique. Yellow = input.
B4: Player ID | C4: Player name | D4: Team / group | E4: Bats (R/L/S) | F4: Readiness level | G4: Current focus | H4: Coaching cue | I4: Assigned drill IDs | J4: Review date | K4: Notes

Sheet Drill Index
B1: ← Contents
B2: Drill Index — 40 Hitting Drills
B3: Click a drill name to open its full entry.
B5: ID | C5: Section | D5: Drill (click to open) | E5: Level | F5: Primary cue | G5: Suggested round
B6: H01 | C6: A – Tee Contact & Barrel Control | D6: Middle Tee Contact Baseline | E6: All | F6: Square it up, then add speed. | G6: 4–6 swings
B7: H02 | C7: A – Tee Contact & Barrel Control | D7: Inside Tee Contact Point | E7: All | F7: Quick turn, clean contact. | G7: 4–6 swings
B8: H03 | C8: A – Tee Contact & Barrel Control | D8: Outside Tee Opposite-Field Drive | E8: All | F8: Let it travel; drive through it. | G8: 4–6 swings
B9: H04 | C9: A – Tee Contact & Barrel Control | D9: Top-of-Zone Tee | E9: All | F9: Match the high pitch. | G9: 5 high + 5 middle
B10: H05 | C10: A – Tee Contact & Barrel Control | D10: Bottom-of-Zone Tee | E10: All | F10: Get to the low pitch, then turn. | G10: 4–6 swings
B11: H06 | C11: A – Tee Contact & Barrel Control | D11: Low-Middle-High Tee Sequence | E11: Developing+ | F11: Match the height. | G11: 2 ladders (6 swings)
B12: H07 | C12: A – Tee Contact & Barrel Control | D12: Full Strike-Zone Tee Map | E12: Developing+ | F12: Each zone has its own contact point. | G12: 9 + 2–4 repeat swings
B13: H08 | C13: A – Tee Contact & Barrel Control | D13: Inside-Outside Tee Switch | E13: Developing+ | F13: Same landing, different contact point. | G13: 6 swings (3 each)
B14: H09 | C14: A – Tee Contact & Barrel Control | D14: Coach-Called Location Tee | E14: Developing+ | F14: Match the contact to the location. | G14: 6 swings
B15: H10 | C15: A – Tee Contact & Barrel Control | D15: Reduced-Ball Tee Precision | E15: Developing+ | F15: Find the center. | G15: 4–6 swings
B16: H11 | C16: B – Movement Into Contact | D16: Fixed-Base Tee Swings | E16: All | F16: Stable base, free turn. | G16: 4 + 2 comparison
... B45: H40 | C45: D – Pitch Selection, Counts & Situations | D45: Full-Count Live Battles | E45: Experienced | F45: Compete, then review. | G45: 2–4 at-bats
B47: Total hitting drills | D47: =COUNTIF(B6:B45,"H*") -> 40
B49: Count by section
C50: A – Tee Contact & Barrel Control | D50: =COUNTIF($C$6:$C$45,C50) -> 10
C51: B – Movement Into Contact | D51: =COUNTIF($C$6:$C$45,C51) -> 10
C52: C – Moving-Ball Contact & Timing | D52: =COUNTIF($C$6:$C$45,C52) -> 10
C53: D – Pitch Selection, Counts & Situations | D53: =COUNTIF($C$6:$C$45,C53) -> 10

Sheet Hitting Drills
B1: ← Contents
B2: Hitting Drill Library (H01–H40)
B3: 40 bat-to-ball drills. Rounds are suggested starting points. Use a helmet for all hitting.
B5: ID | C5: Section | D5: Drill | E5: Level | F5: Purpose | G5: Equipment | H5: Setup | I5: Execution steps | J5: Primary cue | K5: Suggested round | L5: Common mistake | M5: Correction | N5: Easier version | O5: Progression | P5: Success criteria / scoring | Q5: Safety
B6: H01 | C6: A – Tee Contact & Barrel Control | D6: Middle Tee Contact Baseline | E6: All | F6: Establish a contact baseline at a comfortable middle location. | G6: Bat, fitted batting helmet, adjustable tee, practice balls, hitting net or cage | H6: Tee at a comfortable middle-height, middle-of-plate location slightly in front of the plate. Broad center-field target on the net. | I6: 1) Take two easy rehearsal swings. 2) Hit 4–6 balls at controlled effort toward the center target. 3) Reset fully between swings. 4) Build to normal game intent on the last 2. | J6: Square it up, then add speed. | K6: 4–6 swings | L6: Chasing distance and losing balance on every swing. | M6: Score solid contact first; add intent only when contact stays solid. | N6: Larger target; lighter effort. | O6: Alternate with H04/H05 heights; move to H22. | P6: 4 of 6 solid contacts toward the broad target. | Q6: Clear swing radius; no one stands near the hitter or in front of the net; helmet on; check tee stability.
B7: H02 | C7: A – Tee Contact & Barrel Control | D7: Inside Tee Contact Point | E7: All | F7: Deliver the barrel to an inside pitch with contact farther out front. | G7: Bat, fitted batting helmet, adjustable tee, practice balls, hitting net or cage | H7: Tee on the inner half, set farther forward than the away setup. Pull-side gap target. | I7: 1) Confirm the contact point is out front. 2) Take 4–6 swings toward the pull-side gap. 3) Check that contact is on the barrel, not the handle. | J7: Quick turn, clean contact. | K7: 4–6 swings | L7: Tee set too deep, so the hitter gets jammed and learns to push the hands away. | M7: Move the tee forward until barrel contact is comfortable. | N7: Slightly less inside; slower swings. | O7: H08 Inside-Outside Tee Switch; H23 Inside-Lane Front Toss. | P7: Barrel contact on most swings; ball travels toward the pull-side gap. | Q7: Clear swing radius; no one stands near the hitter or in front of the net; helmet on; check tee stability.
B8: H03 | C8: A – Tee Contact & Barrel Control | D8: Outside Tee Opposite-Field Drive | E8: All | F8: Cover the outer half without reaching or diving. | G8: Bat, fitted batting helmet, adjustable tee, practice balls, hitting net or cage | H8: Tee on the outer half at a deeper contact point. Opposite-field gap target. | I8: 1) Let the ball 'travel' deeper. 2) Take 4–6 swings toward the opposite-field gap. 3) Keep the landing controlled; no step across the plate. | J8: Let it travel; drive through it. | K8: 4–6 swings | L8: Stepping across the plate or reaching with the arms to get to the ball. | M8: Use a flat landing marker (H15) and move the tee slightly closer. | N8: Tee slightly less away. | O8: H08; H24 Outside-Lane Front Toss. | P8: Firm opposite-gap contact with a consistent landing. | Q8: Clear swing radius; no one stands near the hitter or in front of the net; helmet on; check tee stability.
B9: H04 | C9: A – Tee Contact & Barrel Control | D9: Top-of-Zone Tee | E9: All | F9: Adjust posture and bat path to a higher pitch; reduce an unnecessary dip-and-lift. | G9: Bat, fitted batting helmet, adjustable tee, practice balls, hitting net or cage | H9: Tee near the top of the hitter's strike zone (not above it), 4–8 inches in front of the plate. | I9: 1) Three slow rehearsal swings. 2) Hit 5 balls at controlled effort aiming for line drives. 3) Hit 5 from a middle-height tee. 4) Alternate high and middle. | J9: Match the high pitch. | K9: 5 high + 5 middle | L9: Coaching it as 'swing down' or chopping at every pitch. | M9: Ask for firm line drives, not ground balls; keep the normal swing shape. | N9: Tee slightly lower; controlled effort. | O9: H06 ladder; H25 high-low toss. | P9: Line drives without a large dip-and-lift; contact holds when the tee returns to middle. | Q9: Clear swing radius; no one stands near the hitter or in front of the net; helmet on; check tee stability.
B10: H05 | C10: A – Tee Contact & Barrel Control | D10: Bottom-of-Zone Tee | E10: All | F10: Adjust to lower strikes without collapsing or reaching. | G10: Bat, fitted batting helmet, adjustable tee, practice balls, hitting net or cage | H10: Tee near the bottom of the hitter's strike zone, slightly in front of the plate. | I10: 1) Rehearse matching the low height with the legs and posture. 2) Hit 4–6 balls toward a broad line-drive target. 3) Reset between swings. | J10: Get to the low pitch, then turn. | K10: 4–6 swings | L10: Dropping the back shoulder to scoop, or bending only at the waist. | M10: Lower the target height expectation; use H06 to contrast heights. | N10: Tee slightly higher. | O10: H06; H25. | P10: Firm contact without falling off balance. | Q10: Clear swing radius; no one stands near the hitter or in front of the net; helmet on; check tee stability.
B11: H06 | C11: A – Tee Contact & Barrel Control | D11: Low-Middle-High Tee Sequence | E11: Developing+ | F11: Adjust barrel delivery to pitch height at a consistent plate location. | G11: Bat, fitted batting helmet, adjustable tee, practice balls, hitting net or cage | H11: One tee moved through low, middle, and high heights at the same plate location. | I11: 1) Low → middle → high, one swing each. 2) Repeat. 3) Then use a changing order the hitter doesn't choose. | J11: Match the height. | K11: 2 ladders (6 swings) | L11: Using the identical swing for every height. | M11: Pause between heights and name the height before each swing. | N11: Two heights only. | O11: H07; H25. | P11: Solid contact at all three heights in at least one ladder. | Q11: Clear swing radius; no one stands near the hitter or in front of the net; helmet on; check tee stability.
B12: H07 | C12: A – Tee Contact & Barrel Control | D12: Full Strike-Zone Tee Map | E12: Developing+ | F12: Explore contact across three heights and three plate locations. | G12: Bat, fitted batting helmet, adjustable tee, practice balls, hitting net or cage | H12: Tape a 3×3 grid on the plate area or use markers; move the tee through the nine zones. | I12: 1) One swing per zone in a set order. 2) Note zones with weak contact. 3) Repeat the two weakest zones. | J12: Each zone has its own contact point. | K12: 9 + 2–4 repeat swings | L12: Leaving the tee at the same depth for inside and outside. | M12: Inside farther forward; outside deeper. | N12: Use only middle row (3 zones). | O12: H27 Mixed-Location Read Toss. | P12: Identifies weak zones; solid contact improves on the repeat swings. | Q12: Clear swing radius; no one stands near the hitter or in front of the net; helmet on; check tee stability.
B13: H08 | C13: A – Tee Contact & Barrel Control | D13: Inside-Outside Tee Switch | E13: Developing+ | F13: Change contact depth while keeping the landing consistent. | G13: Bat, fitted batting helmet, adjustable tee, practice balls, hitting net or cage; flat landing marker | H13: Two tees (or one moved) set inside/forward and away/deeper. Landing marker on the ground. | I13: 1) Alternate inside and away. 2) Keep the same landing spot. 3) Seek pull-gap contact inside and opposite-gap contact away. | J13: Same landing, different contact point. | K13: 6 swings (3 each) | L13: Changing the stride direction to reach each location. | M13: Return to H15 landing-spot work, then retry. | N13: Two consecutive swings per location. | O13: H26 In-Out Location Toss. | P13: Consistent landing on at least 5 of 6 swings. | Q13: Clear swing radius; no one stands near the hitter or in front of the net; helmet on; check tee stability.
B14: H09 | C14: A – Tee Contact & Barrel Control | D14: Coach-Called Location Tee | E14: Developing+ | F14: Connect pitch location with an appropriate contact plan. | G14: Bat, fitted batting helmet, adjustable tee, practice balls, hitting net or cage | H14: Coach repositions the tee before the hitter sets up. Broad pull, middle, and opposite targets. | I14: 1) Coach sets inside, middle, or away. 2) Hitter names the intended broad target. 3) One swing, then change location. | J14: Match the contact to the location. | K14: 6 swings | L14: Forcing every pitch opposite field, or slicing weakly and calling it success. | M14: Score solid contact and direction separately. | N14: Two locations only. | O14: H27; H32. | P14: Solid contact + intended direction on 4 of 6. | Q14: Clear swing radius; no one stands near the hitter or in front of the net; helmet on; check tee stability.
B15: H10 | C15: A – Tee Contact & Barrel Control | D15: Reduced-Ball Tee Precision | E15: Developing+ | F15: Make centered contact the task. | G15: Bat, helmet, compatible tee, suitable smaller practice balls, net | H15: Tee sized for the smaller ball at a comfortable middle location. | I15: 1) Normal two-handed swings. 2) Score clean, centered contact. 3) Finish with 2 normal-ball swings. | J15: Find the center. | K15: 4–6 swings | L15: Slowing the swing to guide the bat. | M15: Keep normal intent; accept misses as information. | N15: Normal ball on a tee. | O15: H22 with normal balls. | P15: Centered contact on at least half the swings without slowing down. | Q15: Clear swing radius; no one stands near the hitter or in front of the net; helmet on; check tee stability.
B16: H11 | C16: B – Movement Into Contact | D16: Fixed-Base Tee Swings | E16: All | F16: Simplify the swing and isolate rotation and contact. | G16: Bat, fitted batting helmet, adjustable tee, practice balls, hitting net or cage | H16: Feet start near the hitter's normal landing width. Middle tee. | I16: 1) Small gentle load. 2) Swing without stepping. 3) Let the hips and shoulders turn naturally. 4) Finish with 2 normal-stride swings for comparison. | J16: Stable base, free turn. | K16: 4 + 2 comparison | L16: Holding the front shoulder or knee closed on purpose. | M16: Allow the back foot and hips to rotate; judge balance, not closedness. | N16: Slower effort. | O16: H12; H13. | P16: Balanced finish and solid contact; compare with normal swings. | Q16: Clear swing radius; no one stands near the hitter or in front of the net; helmet on; check tee stability.
... B45: H40 | C45: D – Pitch Selection, Counts & Situations | D45: Full-Count Live Battles | E45: Experienced | F45: Integrate recognition, decisions, timing, and contact. | G45: Bat, fitted helmet, baseballs, L-screen for the pitcher, cage or field, catcher gear if a catcher is used, score sheet | H45: Complete at-bats from 0–0 with a score sheet. | I45: 1) Track balls, strikes, takes, fouls, and outcomes. 2) Minimal coaching during the at-bat. 3) Review afterward. | J45: Compete, then review. | K45: 2–4 at-bats | L45: Coaching mechanics between every pitch. | M45: Save feedback for after the at-bat. | N45: Count-start rounds (H35–H37). | O45: Game play. | P45: Decision and contact rates hold up against live pitching. | Q45: Pitcher behind an L-screen; follow league helmet and catcher-gear rules; control pitch counts for whoever throws; clear on-deck area.

Sheet Med Ball Library
B1: ← Contents
B2: Medicine-Ball Library (M01–M14)
B3: Supporting power work — not counted in the 40 hitting drills. Use one drill per session, then return to hitting.
B5: ID | C5: Exercise | D5: Stage / category | E5: Purpose | F5: Setup | G5: Steps | H5: Cue | I5: Starting dose | J5: Rest | K5: Pair with hitting drill | L5: Watch for | M5: Ready to progress when | N5: Safety
B6: M01 | C6: Standing Hip-Turn Toss | D6: 2 – Stationary rotation | E6: Load the rear hip and turn to deliver force without managing a stride. | F6: Side-on to the wall, athletic stance, ball near the rear hip. | G6: 1) Small load into the rear hip. 2) Rotate through hips and torso. 3) Release toward the target. 4) Let the feet turn. 5) Reset fully. | H6: Load the hip, turn, release. | I6: 2 × 3 per side | J6: 60–120 sec | K6: H11, H01 | L6: Arm-only throws; leaning back; feet stuck while twisting. | M6: Fast, repeatable release and controlled finish. | N6: Use a ball rated for the impact and a medicine-ball-rated wall or clear designated area; let rebounds settle; stop for pain.
B7: M02 | C7: Stride-Hold Turn Throw | D7: Bridge (coaching adaptation) | E7: Connect a repeatable landing with the following turn. | F7: Flat landing marker; ball near the rear hip; side-on to the target. | G7: 1) Small controlled stride. 2) Brief pause at landing. 3) Check landing direction. 4) Rotate and release. 5) Later remove the pause. | H7: Land on your spot, then turn. | I7: 2 × 3 per side | J7: 60–120 sec | K7: H15, H13, H14 | L7: Cross-stepping, sweeping open, or locking the front foot closed. | M7: Lands on target with a controlled throw. | N7: Use a ball rated for the impact and a medicine-ball-rated wall or clear designated area; let rebounds settle; stop for pain.
B8: M03 | C8: Split-Stance Controlled-Turn Toss | D8: 1 – Stationary anti-rotation | E8: Accept force on the front side with controlled upper-back rotation. | F8: Comfortable split stance side-on to the wall; lead knee softly bent. | G8: 1) Hold the stance. 2) Controlled upper-back turn. 3) Keep the pelvis relatively quiet. 4) Finish without falling sideways. | H8: Strong base, smooth turn. | I8: 2 × 2–3 per side | J8: 60–90 sec | K8: H11, H01 | L8: Twisting through the low back; locking the front knee. | M8: Stable base and smooth release. | N8: Use a ball rated for the impact and a medicine-ball-rated wall or clear designated area; let rebounds settle; stop for pain.
B9: M04 | C9: Turn-and-Push Throw | D9: 2 – Stationary rotation | E9: Feel the body turn deliver the arms instead of reaching outward early (casting). | F9: Side-on; ball near the rear shoulder with the other hand supporting. | G9: 1) Gentle rear-hip load. 2) Turn through lower body and torso. 3) Short shot-put release. 4) Arm extends at the finish. | H9: Let the turn deliver the ball. | I9: 2 × 3 per side | J9: 60–120 sec | K9: H12, H13 | L9: Pushing the ball before the body turns; back arching; shoulder discomfort. | M9: Coordinated release without an early push. | N9: Use a ball rated for the impact and a medicine-ball-rated wall or clear designated area; let rebounds settle; stop for pain.
B10: M05 | C10: Back-Step Load Toss | D10: 4 – Eccentric preload | E10: Get into and out of the rear hip using the stretch-shortening cycle. | F10: Side-on; light ball near the rear hip; clear space. | G10: 1) Small step back with the rear foot. 2) Accept the load in the rear hip. 3) Reverse toward the lead side. 4) Rotate and release. | H10: Get into the hip, then get out. | I10: 2 × 3 per side | J10: 90–120 sec | K10: H16, H22 | L10: Big backward lunge; drifting forward early; arm-first throw. | M10: Controlled preload with a quick reversal. | N10: Use a ball rated for the impact and a medicine-ball-rated wall or clear designated area; let rebounds settle; stop for pain. Advanced: supervise.
B11: M06 | C11: Crossover-Step Turn Throw | D11: 3 – Momentum rotation | E11: Create momentum and transfer it into the front side. | F11: Side-on; short approach space. | G11: 1) Small step toward the target with the lead foot. 2) Rear foot steps behind. 3) Replant lead foot, rotate, throw. | H11: Carry the momentum into the turn. | I11: 2 × 3 per side | J11: 90–120 sec | K11: H22, H28 | L11: Running approach; uncontrolled landing; heavy ball slowing everything down. | M11: Controlled approach and lead-side support. | N11: Use a ball rated for the impact and a medicine-ball-rated wall or clear designated area; let rebounds settle; stop for pain. Advanced: supervise.
B12: M07 | C12: Kneeling Controlled-Turn Throw | D12: 1 – Stationary anti-rotation | E12: Simplify the lower body to practice upper-back turn and a short release. | F12: Kneel on a pad, one knee down; ball near the rear shoulder. | G12: 1) Tall position. 2) Small upper-back turn. 3) Short shot-put throw. 4) Finish without arching. | H12: Quiet base, smooth turn. | I12: 2 × 2–3 per side | J12: 60–90 sec | K12: H12 | L12: Low-back twisting; arching; shoulder discomfort. | M12: Smooth release from a quiet base. | N12: Use a ball rated for the impact and a medicine-ball-rated wall or clear designated area; let rebounds settle; stop for pain.
B13: M08 | C13: Shuffle-Into-Turn Toss | D13: 3 – Momentum rotation | E13: Add controlled lateral movement before the throw. | F13: Side-on; room for one short shuffle. | G13: 1) One small lateral shuffle toward the target. 2) Establish lead-side support. 3) Rotate and throw. | H13: Move smoothly, turn fast. | I13: 2 × 3 per side | J13: 90–120 sec | K13: H22 | L13: Crossing feet; running approach; throwing before the lead foot lands. | M13: Controlled shuffle and landing. | N13: Use a ball rated for the impact and a medicine-ball-rated wall or clear designated area; let rebounds settle; stop for pain.
B14: M09 | C14: Reverse-Shuffle Turn Toss | D14: 3 – Momentum (advanced) | E14: Control and redirect momentum before rotating. | F14: Side-on; extra clear space. | G14: 1) Small move away from target. 2) Reverse into a short shuffle. 3) Establish support. 4) Rotate and release. | H14: Control the change, then accelerate. | I14: 1–2 × 2 per side | J14: ~2 min | K14: H22, H40 | L14: Slipping; big backward move; uncontrolled landing. | M14: Masters M08 first. | N14: Use a ball rated for the impact and a medicine-ball-rated wall or clear designated area; let rebounds settle; stop for pain. Advanced: supervise.
B15: M10 | C15: Overhead Ball Slam | D15: General power | E15: Explosive total-body action without a rotational step. | F15: Slam-compatible, low-bounce ball; suitable floor. | G15: 1) Raise the ball overhead without arching. 2) Drive it into the floor in front. 3) Keep face and feet clear. 4) Let it settle. | H15: Drive it down, finish balanced. | I15: 1–2 × 3 | J15: 60–120 sec | K15: H01 | L15: Excessive back extension; chasing rebounds. | M15: Controlled, repeatable slams. | N15: Slam ball only; never a wall ball. Use a ball rated for the impact and a medicine-ball-rated wall or clear designated area; let rebounds settle; stop for pain.
B16: M11 | C16: Alternating Side Slam | D16: General power | E16: Add lateral movement to the Overhead Ball Slam (M10). | F16: Light slam-compatible ball. | G16: 1) Lift overhead. 2) Small weight shift and slam just outside one foot. 3) Reset; alternate sides. | H16: Shift under control, slam beside you. | I16: 1–2 × 2 per side | J16: 60–120 sec | K16: H01, H22 | L16: Big sideways bend; slamming near the foot. | M16: Controlled M10 first. | N16: Slam ball only. Use a ball rated for the impact and a medicine-ball-rated wall or clear designated area; let rebounds settle; stop for pain.
... B19: M14 | C19: Double-Hop Load Toss | D19: 5 – Preload + momentum | E19: Combine rear-hip preload with momentum into the front side. | F19: Learn footwork without a ball first; light ball. | G19: 1) Two small controlled hops. 2) Accept the preload in the rear hip. 3) Redirect toward the lead side. 4) Rotate and release. | H19: Absorb, redirect, release. | I19: 1–2 × 2 per side | J19: ~2 min | K19: H22, H40 | L19: Hops become a run; unstable landings; forced separation. | M19: Controls M05 and M06 separately. | N19: Use a ball rated for the impact and a medicine-ball-rated wall or clear designated area; let rebounds settle; stop for pain. Not for beginners; supervise.

Sheet Med Ball Progression
B1: ← Contents
B2: Medicine-Ball Progression, Loading & Ball Weight
B5: Five-stage rotational progression (readiness ladder, not a calendar)
B6: Stage | C6: Main demand | D6: Example drills | E6: Establish before advancing | F6: Reason to stay here
B7: 1 | C7: Stationary anti-rotation | D7: M03, M07 | E7: Stable base, controlled upper-back movement | F7: Low-back compensation or base can't be controlled
B8: 2 | C8: Stationary rotation | D8: M01, M04 | E8: Coordinated hip load, turn, and release | F8: Loading or release inconsistent
B9: 3 | C9: Momentum rotation | D9: M06, M08, M09 | E9: Controlled approach and lead-side support | F9: Approach disrupts balance or timing
B10: 4 | C10: Eccentric preload | D10: M05 | E10: Accept and reverse rear-hip loading | F10: Rear-hip load can't be controlled
B11: 5 | C11: Preload + momentum | D11: M14 | E11: Control of stages 3 and 4 together | F11: Hops create instability
B12: Stages 3–5 are too advanced for many 13–15-year-olds without foundational strength and body awareness. Add only one new demand at a time.
B14: Readiness checks
B15: # | C15: Check
B16: 1 | C16: No pain during or after the current drill.
B17: 2 | C17: Repeatable setup and finish.
B18: 3 | C18: Fast, confident release (not a heavy heave).
B19: 4 | C19: No major compensation (arching, forced twisting) to complete the throw.
B20: 5 | C20: Last rep looks as controlled as the first.
B21: 6 | C21: Performs without constant correction.
B22: 7 | C22: Hitting afterward stays productive.
B24: Choosing ball weight
B25: Step | C25: Action
B26: 1 | C26: Start with a light ball suited to the drill (wall ball for wall throws, slam ball for stomps).
B27: 2 | C27: Perform 2–3 controlled rehearsal throws.
B28: 3 | C28: Check: quick acceleration without strain? body contributes? comfortable finish? consistent movement?
B29: 4 | C29: If trying the next weight up, repeat the same drill from the same setup after recovery.
B30: 5 | C30: Return to the lighter ball if speed or control clearly drops. There is no requirement to keep adding weight.
B32: Starting doses (sets × reps per side)
C33: Drill | D33: Dose | E33: Rest | F33: Working throws
C34: M01 Standing Hip-Turn Toss / M04 Turn-and-Push Throw | D34: 2 × 3 per side | E34: 60–120 sec | F34: 12 throws
C35: M05 Back-Step Load Toss | D35: 2 × 3 per side | E35: 90–120 sec | F35: 12 throws
C36: M06 / M08 momentum | D36: 2 × 3 per side | E36: 90–120 sec | F36: 12 throws
C37: M14 Double-Hop Load Toss (prepared athletes) | D37: 1–2 × 2–3 per side | E37: ~2 min+ | F37: 4–12 throws
C38: M10 Overhead Ball Slam | D38: 1–2 × 3 | E38: 60–120 sec | F38: 3–6 throws
C39: Youth first exposure | D39: 1 × 2 each direction | E39: Full recovery | F39: 4 throws
B40: Based on common youth power-training guidelines (1–3 sets of 3–6 reps, not to failure). Count one throw as one rep; 'per side' doubles the total.
B42: Common mistakes
C43: Mistake | D43: What you see | F43: Correction
C44: Drifting instead of loading the rear hip | D44: Head and torso move forward early; arms late | F44: Shorten the step or remove hops; rehearse the load; return to stationary.
C45: Step or hops too large | D45: Backward lunge, running approach, stumbles | F45: Reduce range; footwork without a ball first.
C46: Arms before the body | D46: Slow shove despite an aggressive approach | F46: Remove the approach; light ball; stationary throw.
...

Sheet Youth Games
B1: ← Contents
B2: Youth Games (G01–G05)
B3: Short turns, big targets, everyone succeeds. No penalty reps, elimination, or speed leaderboards.
B5: ID | C5: Game | D5: Uses | E5: Equipment | F5: How to play | G5: Cue | H5: Scale down | I5: Scoring
B6: G01 | C6: Target Zone Throw | D6: Standing Hip-Turn Toss (M01) | E6: Light ball; 2–3 large tape/chalk target zones named after stadiums; rated wall; start mark; waiting line | F6: Player picks a stadium; 2 throws each direction; a point for reaching the zone; recognize a controlled finish and safe reset. | G6: Pick your stadium and send it. | H6: Widen the target or move closer. | I6: 1 point per zone hit + 1 for a controlled finish
B7: G02 | C7: Personal Best Round | D7: Standing Hip-Turn Toss (M01) | E7: Same targets; clipboard or whiteboard | F7: 4 planned throws (2 each direction); record hits; after recovery, an optional second round; compare only with the player's own first round. | G7: Can you make your next round more consistent? | H7: Fewer throws; larger target. | I7: Own-round comparison; celebrate repeating a good round
B8: G03 | C8: Team Target Goal | D8: Standing Hip-Turn Toss (M01) | E8: Same targets; cones for waiting positions; shared scorecard | F8: Set a shared goal (e.g., 6 target hits from everyone's scheduled throws). Players take turns; coach clears area before retrieval. No penalty throws or push-ups. | G8: Every controlled throw helps the team. | H8: Lower the team goal. | I8: Team total vs. achievable goal
B9: G04 | C9: Throw-to-Swing Combo | D9: M01 → H01 → H22 | E9: Light ball, targets, tee, bat, fitted helmet, practice balls, net/cage, protective screen | F9: 2 controlled throws each direction; recover; 4 tee swings to a broad target; if comfortable, 4 predictable front tosses. Player chooses middle or opposite target. | G9: Turn and throw. / See it and square it. | H9: Tee only; soft ball for the throw. | I9: Solid contacts out of swings
B10: G05 | C10: Solid Contact Points Game | D10: H01, H22, H33 | E10: Tee or comfortable front toss; large safe target area; appropriately sized bat; helmet | F10: 3–4 swings per turn; score solid contact toward a broad target; rotate players; add a moving ball only when comfortable; finish with a short swing/take decision game. | G10: Hit your pitch hard. | H10: Tee only; bigger target. | I10: 1 point per solid contact; 1 per correct swing/take

Sheet Rehearsals
B1: ← Contents
B2: Rehearsals & Feedback Tools (R01–R07)
B3: Not counted as hitting drills. Use briefly, then return to bat-to-ball work.
B5: ID | C5: Activity | D5: Purpose | E5: Equipment | F5: How | G5: Cue | H5: Feeds into
B6: R01 | C6: No-Bat Landing Rehearsal | D6: Find the intended landing without a swing. | E6: Flat marker | F6: Load and stride to the mark 3–5 times; freeze and check; no bat needed. | G6: Land on your spot. | H6: H15
B7: R02 | C7: Lift-and-Balance Rehearsal | D7: Feel rear-side support before landing. | E7: Flat marker | F7: Small load; lift front foot slightly; brief hold; place at the mark balanced. | G7: Load, move, arrive balanced. | H7: H16
B8: R03 | C8: Hand-Position Freeze Check | D8: Arrive in a usable launch position. | E8: Mirror or phone video | F8: Load, stride, pause; check hands near the rear shoulder, not collapsed to the waist. | G8: Arrive ready to turn. | H8: H13
B9: R04 | C9: Band-Feedback Load Rehearsal (optional) | D9: Feedback for the move into launch; NOT a resisted swing. | E9: Very light band with handle, smooth stable anchor at loaded-hand height on the catcher side | F9: Light tension; small load and stride; pause; slight hip opening without yanking the arms; return slowly; repeat unresisted. | G9: Feel the load; don't fight the band. | H9: H13, H14
B10: R05 | C10: Guess-Then-Check Round | D10: Connect feel with results in high-intent sessions. | E10: Tee or toss; optional radar/sensor | F10: 3–5 swings with one task; hitter predicts best swing; compare with contact, numbers, and video; change one thing or nothing; repeat. | G10: Fast swing, clear target. | H10: H01, H22
B11: R06 | C11: Feel vs. Film Check | D11: Self-assess one checkpoint accurately. | E11: Phone on tripod; Video Log | F11: Record 3 swings; hitter labels each met/missed/unsure before viewing; review; count matches. | G11: Tell me what you felt, then let's check. | H11: Any
B12: R07 | C12: Rhythm Reset Round | D12: Recover when a hitter is forcing intent. | E12: None | F12: End the round; check discomfort/fatigue; 2–3 rhythm swings; one short retest round; if quality is still worse, reduce difficulty or end high-intent work. | G12: Find the rhythm, then add speed. | H12: Any
B14: Band safety: Band: inspect band and anchor before use; keep the line of pull away from the face; never attach to a bat; no full-speed swings against a band; stop for strain or pain.

Sheet Warm-Up Routines
B1: ← Contents
B2: Warm-Up Routines (WR1–WR6)
B3: Easy movement → mobility → progressively faster, baseball-specific work.
B5: ID | C5: Routine | D5: Time | E5: Use for | F5: Sequence (see Warm-Up Library) | G5: Coaching note
B6: WR1 | C6: Standard Hitting Warm-Up | D6: 10–15 min | E6: Before tee, toss, or batting practice | F6: WU01 → WU02 → WU03 → WU04/WU05 → WU06 → WU08 → WU09 → WU11 (2 easy + 2 moderate) → WU12 (4–6 tee contacts) → WU13 if needed | G6: Start easy; build gradually toward practice speed.
B7: WR2 | C7: Youth Simplified Warm-Up | D7: 6–10 min | E7: Younger or beginner players | F7: WU01 (game-style) → WU03 → WU05 → WU09 → WU11 (3 easy swings) → WU12 (3–4 tee contacts) | G7: Familiar movements; short instructions; finish engaged, not tired.
B8: WR3 | C8: Medicine-Ball-to-Hitting Prep | D8: 12–18 min | E8: Sessions with a med-ball power block | F8: WR1 general portion → WU14 rehearsal throws → planned med-ball block (Med Ball Library) → 1–2 min recovery → WU11 → WU12 → WU13 | G8: Throws before hitting only if the hitter stays coordinated.
B9: WR4 | C9: Game-Day Routine | D9: 10–15 min | E9: Before games | F9: WU01 → WU02 → WU04 → WU06 → WU08 → WU09 → WU11 → WU12/WU13 if available | G9: Familiar preparation only — no new drills, no med-ball records.
B10: WR5 | C10: Between-Innings / Long-Wait Reset | D10: 2–4 min | E10: Athlete already warmed up who has been sitting | F10: WU03 (short) → WU08 → WU09 → WU11 (2–3 progressive swings, safe area) | G10: Follow league rules for on-deck swings and timing.
B11: WR6 | C11: Cold-Weather Adjustment | D11: 15–20 min | E11: Cold days | F11: Extend WU01–WU02; repeat WU06–WU08; extra progressive dry swings before any contact | G11: Layer clothing; extend gradually; don't rush to full intent.

Sheet Warm-Up Library
B1: ← Contents
B2: Warm-Up Library (WU01–WU14)
B5: ID | C5: Activity | D5: Purpose | E5: How | F5: Dose | G5: Cue | H5: Easier option
B6: WU01 | C6: Easy Locomotion | D6: Raise body temperature | E6: Walk, march, or jog easily. | F6: 2–3 min | G6: Easy and relaxed. | H6: Walk only
B7: WU02 | C7: Lateral Shuffles | D7: Lateral movement and footwork | E7: Short controlled shuffles both directions. | F7: 2 × 10 m each way | G7: Light, quick feet. | H7: Side steps
B8: WU03 | C8: Knee Lifts / Skips | D8: Hip and leg preparation | E8: Marching knee lifts progressing to easy skips. | F8: 2 × 10 m | G8: Tall and rhythmic. | H8: Marching only
B9: WU04 | C9: Bodyweight Squats | D9: Lower-body mobility | E9: Comfortable-depth squats. | F9: 6–8 reps | G9: Sit and stand smoothly. | H9: Shallower depth
B10: WU05 | C10: Reverse Lunges | D10: Single-leg control | E10: Controlled step-back lunges, alternating. | F10: 4–5 per side | G10: Step back, stand tall. | H10: Hold support
B11: WU06 | C11: Lateral Weight Shifts | D11: Hip loading side to side | E11: Wide stance; shift weight hip to hip. | F11: 6 per side | G11: Sit into each hip. | H11: Smaller range
B12: WU07 | C12: Hip Hinges | D12: Posture and hamstrings | E12: Push hips back with a long spine, then stand. | F12: 6–8 reps | G12: Hips back, chest proud. | H12: Hands on thighs
B13: WU08 | C13: Trunk Turns | D13: Comfortable rotation | E13: Controlled trunk rotations in a batting-width stance. | F13: 6 per side | G13: Turn smoothly; no forcing. | H13: Smaller range
B14: WU09 | C14: Arm Circles & Wrist Prep | D14: Shoulder and wrist readiness | E14: Small-to-large arm circles; wrist circles and gentle flexion/extension. | F14: 10 each | G14: Smooth and easy. | H14: Smaller circles
B15: WU10 | C15: Band Pull-Aparts (optional) | D15: Upper-back activation | E15: Light band pulled apart at chest height. | F15: 8–10 reps | G15: Squeeze shoulder blades lightly. | H15: Skip
B16: WU11 | C16: Progressive Dry Swings | D16: Groove the swing | E16: Easy → moderate → normal effort swings with the game bat. | F16: 4–6 swings | G16: Normal swing, free turn. | H16: Fewer swings
... B19: WU14 | C19: Med-Ball Rehearsal Throws (optional) | D19: Prepare for a power block | E19: 2–3 easy stationary throws per side (M01). | F19: 2–3 per side | G19: Easy load, easy turn. | H19: Skip

Sheet Troubleshooting
B1: ← Contents
B2: Troubleshooting Common Swing Flaws (T01–T18)
B3: Observe → form a hypothesis → test one change → retest. One visible result can have several causes.
B5: ID | C5: Issue | D5: What you see | E5: Checks to distinguish causes | F5: Possible contributors | G5: Recommended drills | H5: Cue | I5: Avoid | J5: Progress marker | K5: Retest
B6: T01 | C6: Stepping out / front-hip bailout | D6: Front foot moves away from the plate before landing, or hip/shoulder pulls away during the turn. | E6: Mark landing spot; compare stride-only, stride-pause, and no-stride swings to see whether it starts before or after landing. | F6: Stride direction habit; early pull of the front side; fear or difficulty with inside pitches; timing. | G6: H15, H16, H11, H24 | H6: Land on your spot. | I6: Locking the toe or knee closed; demanding 'stay closed' through contact. | J6: More consistent landings on comparable swings. | K6: Score 10 swings on landing before and after (Video Log).
B7: T02 | C7: Diving across the plate | D7: Stride lands excessively toward the plate; reaching for away pitches. | E7: Check landing vs. intended line; check whether it happens only on away pitches. | F7: Overcorrecting a bailout; trying to reach outer half; plate position. | G7: H15, H03, H24, H08 | H7: Let it travel; same landing. | I7: Moving the hitter off the plate without checking contact depth first. | J7: Landing stays on line on away pitches. | K7: Retest H08 landing consistency.
B8: T03 | C8: Casting | D8: Hands push outward early; arms extend before the barrel is delivered; wide barrel path. | E8: Pitcher-facing view: distance between hands and torso at swing start. | F8: Sequencing; arms starting the swing; bat too heavy; reaching for outer pitches. | G8: H12, H13, H04, H11 | H8: Turn without reaching. | I8: Hard barriers or rigid poles; telling the hitter to keep the arms bent forever. | J8: Less early outward hand movement on video. | K8: Compare Loaded-Hands Start Tee swings with normal swings.
B9: T04 | C9: Hands drop during the stride | D9: Hands lower relative to the shoulder before or as the forward swing begins. | E9: Chest-facing view; compare starting hand height with landing; check whether delivery is affected. | F9: Load pattern; timing; posture; hands starting too high for comfort. | G9: H13, H14, H12 | H9: Arrive ready, then turn. | I9: Freezing the hands at one height; treating every lowering as a flaw. | J9: More consistent, usable launch position. | K9: Hold vs. Flow Tee Pairs comparison.
B10: T05 | C10: Looping / dip-and-lift swing | D10: Hands or barrel dip then climb back to the ball; many popups or weak contact up in the zone. | E10: Check whether it's a hand dip or a barrel dip; check posture at landing. | F10: Hand drop; posture; excessive attack angle for the pitch. | G10: H04, H06, H25 | H10: Match the high pitch. | I10: 'Swing down' as a universal rule. | J10: Firmer line drives on high-tee and high-toss. | K10: High–middle tee alternation.
B11: T06 | C11: Early shoulder pull | D11: Front shoulder opens before the barrel is delivered; contact weak to the pull side or misses away. | E11: Check landing first (T01); check pitch location. | F11: Bailout; guessing inside; trying to pull everything. | G11: H03, H24, H08, H11 | H11: Turn, don't spin off. | I11: Holding the shoulder shut until after contact. | J11: Firm opposite-gap contact on away pitches. | K11: Away tee/toss scoring.
B12: T07 | C12: Overstriding / lunging | D12: Long stride; head and body drift forward; weak or early contact on off-speed. | E12: Measure stride length on video; compare toe-tap swings. | F12: Trying to generate power with the stride; timing. | G12: H17, H15, H13, H28 | H12: Small and on time. | I12: Eliminating the stride permanently. | J12: Shorter, repeatable stride with solid contact. | K12: Short-Tap Stride Tee vs. normal comparison.
B13: T08 | C13: Staying back / spinning | D13: Weight stays over the back leg; hitter spins without moving into the front side. | E13: Chest-facing view of weight transfer at contact. | F13: Overcoaching 'stay back'; fear of lunging. | G13: H18, H16, H14 | H13: Move, land, turn. | I13: Cueing 'stay back' more. | J13: Balanced finish over a supported front side. | K13: Step-In Momentum Tee vs. normal comparison.
B14: T09 | C14: Late swings / getting jammed | D14: Contact deep and on the handle; foul balls to the opposite side. | E14: Check start timing and contact point vs. pitch location. | F14: Late start; long swing; inside-pitch contact depth. | G14: H22, H28, H23, H02 | H14: Start early, be on time. | I14: Forcing faster hands without fixing start timing. | J14: More on-time contact against toss. | K14: Score on-time contacts out of 6.
B15: T10 | C15: Early swings / rollovers | D15: Weak pull-side grounders; rolling over off-speed or away pitches. | E15: Check contact depth on away pitches; check stride timing. | F15: Early commitment; guessing; contact too far forward away. | G15: H03, H24, H28, H29 | H15: Let it travel. | I15: Telling the hitter to just 'wait' without a timing task. | J15: Fewer rollovers on away tosses. | K15: Away toss contact scoring.
B16: T11 | C16: Weak outside-pitch contact | D16: Soft contact or misses on the outer half. | E16: Check landing (T02) and contact depth. | F16: Reaching; contact too far out front; diving. | G16: H03, H24, H26, H08 | H16: Let it travel; drive through it. | I16: Moving the tee far away so the hitter must reach. | J16: Firm opposite-gap contact. | K16: H24 scoring.
... B23: T18 | C23: Forcing high intent | D23: Effort rises but bat speed or contact repeatedly drops; rushing; old flaws return. | E23: Compare effort report with contact and any measured speed across rounds. | F23: Fatigue; chasing numbers; too much volume. | G23: R07, R05, H01, H22 | H23: Find the rhythm, then add speed. | I23: 'One more until you beat it.' | J23: Speed and contact rise together. | K23: Two-score challenge: speed/intent + solid contacts.
B26: Workflow
C27: Step | D27: Action
C28: 1 Observe | D28: Film 5–10 comparable swings from the same angle; note one checkpoint.
C29: 2 Hypothesis | D29: Pick the most likely cause using the Checks column.
C30: 3 Test | D30: Run one recommended drill with one cue.
C31: 4 Retest | D31: Film the same comparable swings; log in Video Log.
C32: 5 Decide | D32: Keep, adjust, or step back one level. Don't stack corrections.

Sheet Mental Approach
B1: ← Contents
B2: Mental Approach & Pitch Selection
B3: Links to drills H31–H40.
B5: Core principles
B6: Principle | C6: Guidance | D6: Cue
B7: Controllable goals | C7: See the ball, swing at appropriate pitches, know the task, make a committed swing. | D7: See it, choose it, commit.
B8: Decision vs. execution vs. outcome | C8: Score whether the swing/take was appropriate separately from contact and from the result. | D8: Good decision is a win.
B9: Prepared aggression | C9: Be ready to attack your pitch early — ready does not mean required to swing. | D9: Ready to attack.
B10: Attack area vs. strike zone | C10: An attack area is the hitter's chosen damage zone, narrower than the rulebook zone early in counts. | D10: Know what you want.
B11: Confidence | C11: Build from recent good decisions and solid contact, not batting average. | D11: Stack good at-bats.
B12: Focus | C12: One thought per at-bat; save mechanics for practice. | D12: One thought.
B13: Emotional reset | C13: Breathe, step out within league rules, restate the plan. | D13: Breathe, reset, plan.
B15: At-bat routine
B16: Phase | C16: What to do | D16: Cue
B17: Before the at-bat | C17: Watch the pitcher's timing and pitch mix from the dugout. | D17: What is he throwing?
B18: On deck | C18: Time the pitcher with rhythm swings; set one plan. | D18: Time him up.
B19: Before each pitch | C19: Breath; restate the attack area for the count. | D19: My pitch, my zone.
B20: Between pitches | C20: Brief reset within league timing rules; adjust plan to the count. | D20: Next pitch.
B21: After the at-bat | C21: Note one thing about the decision and one about the pitcher — not the result. | D21: What did I learn?
B23: Count approach (adapt to level and team strategy)
B24: Count | C24: Approach | D24: Common error | E24: Practice with
B25: 0–0 | C25: Attack a pitch in your area; take others. | D25: Swinging at anything because it's the first pitch. | E25: H35
B26: 1–0, 2–0, 2–1, 3–1 | C26: Narrow the attack area; look for damage. | D26: Expanding the zone in a hitter's count. | E26: H36
B27: 0–1, 1–1 | C27: Stay with the plan; slightly wider area. | D27: Panicking after one strike. | E27: H32
B28: 0–2, 1–2, 2–2 | C28: Widen to protect the zone; compete; take obvious balls. | D28: Chasing everything to 'protect'. | E28: H37
B29: 3–2 | C29: Compete on strikes; trust the take on clear balls. | D29: Freezing on a hittable strike. | E29: H40
B30: Situations (runner on 2nd/3rd) | C30: Choose a pitch that supports the job. | D30: Forcing one batted-ball type regardless of pitch. | E30: H38, H39
B32: Youth coaching language
B33: Situation | C33: Say | D33: Avoid
B34: After a strikeout | C34: Did you swing at your pitch? That's the part we control. | D34: You have to hit that.
B35: After a good take | C35: Great take — that was a ball. | D35: Why didn't you swing?
B36: After a hard out | C36: That was a strong swing on a good pitch. | D36: Unlucky, you should have had a hit.
B37: Before an at-bat | C37: Look for your pitch and hit it hard. | D37: Don't strike out.

Sheet Session Builder
B1: ← Contents
B2: Session Builder
B3: Templates use workbook IDs. Minutes are estimates — adjust to readiness, not the clock.
B5: S1 – Youth Intro (≈25 min)
B6: Block | C6: Minutes | D6: Activity | E6: IDs | F6: Coach focus
B7: Warm-up | C7: 7 | D7: WR2 Youth Simplified Warm-Up | E7: WR2 | F7: Ready, not tired
B8: Contact | C8: 5 | D8: Middle Tee Contact Baseline | E8: H01 | F8: Square it up
B9: Game | C9: 6 | D9: Solid Contact Points Game | E9: G05 | F9: Fun + solid contact
B10: Moving ball | C10: 5 | D10: Side-Angle Toss Contact | E10: H21 | F10: Track it
B11: Wrap-up | C11: 2 | D11: 'What was the most fun part?' | E11: — | F11: Enjoyment
B12: Total minutes | C12: =SUM(C7:C11) -> 25
B14: S2 – Bailout / Landing Technical (≈30 min)
B15: Block | C15: Minutes | D15: Activity | E15: IDs | F15: Coach focus
B16: Warm-up | C16: 10 | D16: WR1 Standard Hitting Warm-Up | E16: WR1 | F16: Progressive
B17: Baseline video | C17: 3 | D17: 5 normal tee swings recorded | E17: H01 | F17: Landing checkpoint
B18: Rehearsal | C18: 3 | D18: No-Bat Landing Rehearsal | E18: R01 | F18: Land on your spot
B19: Tee | C19: 6 | D19: Marked Landing Tee, then Fixed-Base Tee Swings | E19: H15, H11 | F19: Free turn
B20: Transfer | C20: 6 | D20: Steady Middle Front Toss, then Outside-Lane Front Toss | E20: H22, H24 | F20: Same landing
B21: Retest | C21: 2 | D21: 5 normal swings recorded | E21: — | F21: Compare with baseline
B22: Total minutes | C22: =SUM(C16:C21) -> 30
B24: S3 – Hand Drop / Casting Technical (≈30 min)
B25: Block | C25: Minutes | D25: Activity | E25: IDs | F25: Coach focus
B26: Warm-up | C26: 10 | D26: WR1 | E26: WR1 | F26: Progressive
B27: Rehearsal | C27: 3 | D27: Hand-Position Freeze Check | E27: R03 | F27: Arrive ready
B28: Tee | C28: 8 | D28: Stride, Hold, Swing Tee → Hold vs. Flow Tee Pairs → Loaded-Hands Start Tee | E28: H13, H14, H12 | F28: Turn from here
B29: Height | C29: 4 | D29: Top-of-Zone Tee | E29: H04 | F29: Match the high pitch
B30: Transfer | C30: 5 | D30: Steady Middle Front Toss | E30: H22 | F30: Same ready position
B31: Total minutes | C31: =SUM(C26:C30) -> 30
B33: S4 – Med-Ball + Hitting Power (≈35 min)
B34: Block | C34: Minutes | D34: Activity | E34: IDs | F34: Coach focus
B35: Warm-up | C35: 12 | D35: WR3 Medicine-Ball-to-Hitting Prep | E35: WR3 | F35: Coordinated
B36: Power block | C36: 6 | D36: One selected drill, 2 × 3 per side (12 throws) | E36: M01 or M05 | F36: Fast, controlled releases
B37: Recovery | C37: 2 | D37: Rest; 2–3 dry swings | E37: WU11 | F37: Reset
B38: Tee | C38: 5 | D38: 4–6 tee swings | E38: H01 | F38: Square it, then add speed
B39: Toss | C39: 8 | D39: Steady Middle Front Toss → Mixed-Location Read Toss with takes | E39: H22, H27 | F39: Attack a good pitch
B40: Total minutes | C40: =SUM(C35:C39) -> 33
B42: S5 – High-Intent Feedback (≈28 min)
B43: Block | C43: Minutes | D43: Activity | E43: IDs | F43: Coach focus
B44: Readiness + warm-up | C44: 7 | D44: Readiness Log check; WR1 | E44: WR1 | F44: Ready and comfortable
B45: Baseline | C45: 3 | D45: 5 tee swings at game intent | E45: H01 | F45: Contact baseline
...

Sheet Parents Guide
B1: ← Contents
B2: Parents' Guide to Home Practice
B3: Short, optional, safe, and fun. One coach-approved goal at a time.
B5: Start here
B6: Step | C6: What to do
B7: Step 1 | C7: Ask the coach for ONE current goal and ONE cue (use the Coach-Parent Plan sheet).
B8: Step 2 | C8: Check willingness: home practice is optional and short.
B9: Step 3 | C9: Check readiness: no pain, not exhausted, not right after a heavy game or pitching day.
B10: Step 4 | C10: Check the space with the Home Safety Checklist.
B11: Step 5 | C11: Pick one session from Sample Home Sessions (10–15 min).
B12: Step 6 | C12: Use the Parent Language guide: praise decisions and effort, not results.
B13: Step 7 | C13: Log the session in the Practice Log with Context = Home.
B14: Step 8 | C14: Stop for pain and tell the coach. Count games, lessons, and team practice before adding home work.
B16: Home safety checklist
B17: Check | E17: Why | G17: Done? (Y/N)
B18: Fitted batting helmet worn for all hitting | E18: Protects against mishits and rebounds
B19: Clear swing radius — no people, pets, cars, or windows nearby | E19: Bats travel farther than expected
B20: Net rated for baseballs and anchored | E20: Prevents rebounds and runaway balls
B21: Tosser behind a protective screen (front toss) or safely offset (side toss) | E21: Protects the parent
B22: Bat sized and league-legal for the player | E22: Correct swing and safety
B23: Soft or practice balls in small spaces | E23: Reduces damage risk
B24: Retrieve balls only when swinging has stopped | E24: Avoids being hit
B25: Dry footing; no practice in lightning or extreme heat | E25: Weather safety
B26: Stop immediately for pain | E26: Pain is not a coaching problem
B28: Home practice menu (reuses workbook drills)
B29: Option | C29: Drill ID | D29: Setup | E29: Swings | F29: Cue | G29: Space
B30: Middle Tee Contact Baseline | C30: H01 | D30: Tee at middle; broad target | E30: 4–6 | F30: Square it up. | G30: Small
B31: Top-of-Zone Tee | C31: H04 | D31: Tee at top of zone | E31: 4–6 | F31: Match the high pitch. | G31: Small
B32: Bottom-of-Zone Tee | C32: H05 | D32: Tee at bottom of zone | E32: 4–6 | F32: Get to the low pitch. | G32: Small
B33: Low-Middle-High Tee Sequence | C33: H06 | D33: Low → middle → high | E33: 6 | F33: Match the height. | G33: Small
B34: Fixed-Base Tee Swings | C34: H11 | D34: Feet near landing width | E34: 4 | F34: Stable base, free turn. | G34: Small
B35: Stride, Hold, Swing Tee | C35: H13 | D35: Middle Tee Contact Baseline | E35: 4 | F35: Arrive ready, then turn. | G35: Small
B36: Marked Landing Tee | C36: H15 | D36: Tape landing mark | E36: 5 | F36: Land on your spot. | G36: Small
B37: Side-Angle Toss Contact | C37: H21 | D37: Parent safely offset | E37: 4–6 | F37: Track it, square it. | G37: Medium
B38: No-Bat Landing Rehearsal | C38: R01 | D38: Tape mark only | E38: 5 | F38: Land on your spot. | G38: Indoor OK
B40: Sample home sessions
B41: Session | C41: Sequence
B42: Quick contact (10 min) | C42: Easy movement → 4 dry swings → H01 × 4 → H04 × 4 → 'What felt good?'
B43: Landing focus (12 min) | C43: Easy movement → R01 × 5 → H15 × 5 → H01 × 4 (marker removed)
B44: Hands/launch focus (12 min) | C44: Easy movement → R03 × 4 → H13 × 4 → H14 × 4 pairs
...

Sheet Coach-Parent Plan
B1: ← Contents
B2: Coach–Parent Home Plan
B3: Coach fills one row per player; share only that player's row with the family.
B4: Player ID | C4: Player name | D4: Current goal | E4: Approved home drills (IDs) | F4: Cue | G4: Restrictions / avoid | H4: Weekly home limit | I4: Review date | J4: Coach | K4: Parent acknowledged (Y/N)
C5: =IF(B5="","",IFERROR(INDEX(Players!$C$5:$C$104,MATCH(B5,Players!$B$5:$B$104,0)),"ID not found"))
C6: =IF(B6="","",IFERROR(INDEX(Players!$C$5:$C$104,MATCH(B6,Players!$B$5:$B$104,0)),"ID not found"))
C7: =IF(B7="","",IFERROR(INDEX(Players!$C$5:$C$104,MATCH(B7,Players!$B$5:$B$104,0)),"ID not found"))
C8: =IF(B8="","",IFERROR(INDEX(Players!$C$5:$C$104,MATCH(B8,Players!$B$5:$B$104,0)),"ID not found"))
C9: =IF(B9="","",IFERROR(INDEX(Players!$C$5:$C$104,MATCH(B9,Players!$B$5:$B$104,0)),"ID not found"))
C10: =IF(B10="","",IFERROR(INDEX(Players!$C$5:$C$104,MATCH(B10,Players!$B$5:$B$104,0)),"ID not found"))
C11: =IF(B11="","",IFERROR(INDEX(Players!$C$5:$C$104,MATCH(B11,Players!$B$5:$B$104,0)),"ID not found"))
C12: =IF(B12="","",IFERROR(INDEX(Players!$C$5:$C$104,MATCH(B12,Players!$B$5:$B$104,0)),"ID not found"))
C13: =IF(B13="","",IFERROR(INDEX(Players!$C$5:$C$104,MATCH(B13,Players!$B$5:$B$104,0)),"ID not found"))
C14: =IF(B14="","",IFERROR(INDEX(Players!$C$5:$C$104,MATCH(B14,Players!$B$5:$B$104,0)),"ID not found"))
C15: =IF(B15="","",IFERROR(INDEX(Players!$C$5:$C$104,MATCH(B15,Players!$B$5:$B$104,0)),"ID not found"))
C16: =IF(B16="","",IFERROR(INDEX(Players!$C$5:$C$104,MATCH(B16,Players!$B$5:$B$104,0)),"ID not found"))
... C64: =IF(B64="","",IFERROR(INDEX(Players!$C$5:$C$104,MATCH(B64,Players!$B$5:$B$104,0)),"ID not found"))

Sheet Practice Log
B1: ← Contents
B2: Practice Log — Hitting
B3: One row per drill round. Yellow = input. Gray = automatic. Leave unassessed measures blank (blank ≠ 0).
B4: Date | C4: Player ID | D4: Player name | E4: Context | F4: Drill ID | G4: Drill name | H4: Minutes (this round) | I4: Swings | J4: Solid contacts | K4: Decision pitches assessed | L4: Correct decisions | M4: Landings assessed | N4: Intended landings | O4: Enjoyment (1–5) | P4: Pain? (Y/N) | Q4: Cue used | R4: Notes | S4: Day key | T4: Day-context key | U4: Entry check
D5: =IF(C5="","",IFERROR(INDEX(Players!$C$5:$C$104,MATCH(C5,Players!$B$5:$B$104,0)),"ID not found")) | G5: =IF(F5="","",IFERROR(INDEX('Hitting Drills'!$D$6:$D$45,MATCH(F5,'Hitting Drills'!$B$6:$B$45,0)),"Not a hitting drill ID")) | S5: =IF(OR(B5="",C5=""),"",IF(COUNTIFS($B$5:B5,B5,$C$5:C5,C5)=1,1,0)) | T5: =IF(OR(B5="",C5="",E5=""),"",IF(COUNTIFS($B$5:B5,B5,$C$5:C5,C5,$E$5:E5,E5)=1,1,0)) | U5: =IF(COUNTA(B5:C5,E5:F5,H5:P5)=0,"",IF(OR(B5="",C5="",E5=""),"Check: date, player, and context required",IF(AND(ISNUMBER(J5),ISNUMBER(I5),J5>I5),"Check: solid contacts > swings",IF(AND(ISNUMBER(L5),ISNUMBER(K5),L5>K5),"Check: correct > assessed decisions",IF(AND(ISNUMBER(N5),ISNUMBER(M5),N5>M5),"Check: intended > assessed landings",IF(AND(ISNUMBER(J5),I5=""),"Check: solid contacts without swings","OK"))))))
D6: =IF(C6="","",IFERROR(INDEX(Players!$C$5:$C$104,MATCH(C6,Players!$B$5:$B$104,0)),"ID not found")) | G6: =IF(F6="","",IFERROR(INDEX('Hitting Drills'!$D$6:$D$45,MATCH(F6,'Hitting Drills'!$B$6:$B$45,0)),"Not a hitting drill ID")) | S6: =IF(OR(B6="",C6=""),"",IF(COUNTIFS($B$5:B6,B6,$C$5:C6,C6)=1,1,0)) | T6: =IF(OR(B6="",C6="",E6=""),"",IF(COUNTIFS($B$5:B6,B6,$C$5:C6,C6,$E$5:E6,E6)=1,1,0)) | U6: =IF(COUNTA(B6:C6,E6:F6,H6:P6)=0,"",IF(OR(B6="",C6="",E6=""),"Check: date, player, and context required",IF(AND(ISNUMBER(J6),ISNUMBER(I6),J6>I6),"Check: solid contacts > swings",IF(AND(ISNUMBER(L6),ISNUMBER(K6),L6>K6),"Check: correct > assessed decisions",IF(AND(ISNUMBER(N6),ISNUMBER(M6),N6>M6),"Check: intended > assessed landings",IF(AND(ISNUMBER(J6),I6=""),"Check: solid contacts without swings","OK"))))))
D7: =IF(C7="","",IFERROR(INDEX(Players!$C$5:$C$104,MATCH(C7,Players!$B$5:$B$104,0)),"ID not found")) | G7: =IF(F7="","",IFERROR(INDEX('Hitting Drills'!$D$6:$D$45,MATCH(F7,'Hitting Drills'!$B$6:$B$45,0)),"Not a hitting drill ID")) | S7: =IF(OR(B7="",C7=""),"",IF(COUNTIFS($B$5:B7,B7,$C$5:C7,C7)=1,1,0)) | T7: =IF(OR(B7="",C7="",E7=""),"",IF(COUNTIFS($B$5:B7,B7,$C$5:C7,C7,$E$5:E7,E7)=1,1,0)) | U7: =IF(COUNTA(B7:C7,E7:F7,H7:P7)=0,"",IF(OR(B7="",C7="",E7=""),"Check: date, player, and context required",IF(AND(ISNUMBER(J7),ISNUMBER(I7),J7>I7),"Check: solid contacts > swings",IF(AND(ISNUMBER(L7),ISNUMBER(K7),L7>K7),"Check: correct > assessed decisions",IF(AND(ISNUMBER(N7),ISNUMBER(M7),N7>M7),"Check: intended > assessed landings",IF(AND(ISNUMBER(J7),I7=""),"Check: solid contacts without swings","OK"))))))
